Started by user [8mha:////4AvbKtqCpWGC4/9vlaAOyQD+y56HOfLOpPpkD7K9YRsAAAAAlx+LCAAAAAAAAP9b85aBtbiIQTGjNKU4P08vOT+vOD8nVc83PyU1x6OyILUoJzMv2y+/JJUBAhiZGBgqihhk0NSjKDWzXb3RdlLBUSYGJk8GtpzUvPSSDB8G5tKinBIGIZ+sxLJE/ZzEvHT94JKizLx0a6BxUmjGOUNodHsLgAzWEgZu/dLi1CL9xJTczDwAj6GcLcAAAAA=[0madmin
Running as SYSTEM
Building in workspace /var/root/.jenkins/workspace/hot_user
using credential root
 > git rev-parse --is-inside-work-tree # timeout=10
Fetching changes from the remote Git repository
 > git config remote.origin.url git@github.com:kirinisland/zaoci-tool.git # timeout=10
Fetching upstream changes from git@github.com:kirinisland/zaoci-tool.git
 > git --version # timeout=10
using GIT_SSH to set credentials 
 > git fetch --tags --force --progress -- git@github.com:kirinisland/zaoci-tool.git +refs/heads/*:refs/remotes/origin/* # timeout=10
 > git rev-parse refs/remotes/origin/master^{commit} # timeout=10
 > git rev-parse refs/remotes/origin/origin/master^{commit} # timeout=10
Checking out Revision b8225cdccd06453ebd834839bcf9a9f3cea9d9f1 (refs/remotes/origin/master)
 > git config core.sparsecheckout # timeout=10
 > git checkout -f b8225cdccd06453ebd834839bcf9a9f3cea9d9f1 # timeout=10
Commit message: "fix hot user bug"
 > git rev-list --no-walk b8225cdccd06453ebd834839bcf9a9f3cea9d9f1 # timeout=10
[hot_user] $ /bin/sh -xe /var/folders/zz/zyxvpxvq6csfxvn_n0000000000000/T/jenkins566196703904321884.sh
+ python3 jobs/hot_user.py
Hot users after date: 2020-04-02 00:00:00
ÁÇπËµûÊúÄÂ§ö: https://api2.bmob.cn/1/classes/EverydayLyric?&limit=10&where={"validStatus": {"$gte": 2, "$lte": 3}, "createdAt": {"$gte": {"__type": "Date", "iso": "2020-04-02 00:00:00"}}}&keys=userId,validStatus,likeCount,commentCount,bookmarkCount&order=-likeCount
[('9b05e67c2de97022', 4, 1, 3, 3), ('oKJKF0vqI1Q4GBOiDJaBVoU7UPFU', 4, None, 2, 3), ('Áß¶ËØ≠ÊôóQ.Y.H', 4, 2, 1, 3), ('Dante', 4, None, 1, 3), ('oKJKF0jojILVq_RS83rRDUtW8kWU', 3, None, 5, 3), ('ÂçÉÈÄ∏Ëæâ', 3, None, 4, 3), ('oKJKF0oJC_fhbFS0qFGgHdOSl9gQ', 3, None, 3, 3), ('1e7d7185d46455bd', 2, None, 2, 3), ('oKJKF0qCnrzorJZpiN44OV7K0D6o', 2, None, 1, 3), ('319f1363d15cf60e', 2, None, 5, 3)]
Traceback (most recent call last):
  File "/Library/Python/3.7/site-packages/urllib3/connectionpool.py", line 672, in urlopen
    chunked=chunked,
  File "/Library/Python/3.7/site-packages/urllib3/connectionpool.py", line 376, in _make_request
    self._validate_conn(conn)
  File "/Library/Python/3.7/site-packages/urllib3/connectionpool.py", line 994, in _validate_conn
    conn.connect()
  File "/Library/Python/3.7/site-packages/urllib3/connection.py", line 360, in connect
    ssl_context=context,
  File "/Library/Python/3.7/site-packages/urllib3/util/ssl_.py", line 370, in ssl_wrap_socket
    return context.wrap_socket(sock, server_hostname=server_hostname)
  File "/Applications/Xcode.app/Contents/Developer/Library/Frameworks/Python3.framework/Versions/3.7/lib/python3.7/ssl.py", line 412, in wrap_socket
    session=session
  File "/Applications/Xcode.app/Contents/Developer/Library/Frameworks/Python3.framework/Versions/3.7/lib/python3.7/ssl.py", line 853, in _create
    self.do_handshake()
  File "/Applications/Xcode.app/Contents/Developer/Library/Frameworks/Python3.framework/Versions/3.7/lib/python3.7/ssl.py", line 1117, in do_handshake
    self._sslobj.do_handshake()
ConnectionResetError: [Errno 54] Connection reset by peer

During handling of the above exception, another exception occurred:

Traceback (most recent call last):
  File "/Library/Python/3.7/site-packages/requests/adapters.py", line 449, in send
    timeout=timeout
  File "/Library/Python/3.7/site-packages/urllib3/connectionpool.py", line 720, in urlopen
    method, url, error=e, _pool=self, _stacktrace=sys.exc_info()[2]
  File "/Library/Python/3.7/site-packages/urllib3/util/retry.py", line 400, in increment
    raise six.reraise(type(error), error, _stacktrace)
  File "/Library/Python/3.7/site-packages/urllib3/packages/six.py", line 734, in reraise
    raise value.with_traceback(tb)
  File "/Library/Python/3.7/site-packages/urllib3/connectionpool.py", line 672, in urlopen
    chunked=chunked,
  File "/Library/Python/3.7/site-packages/urllib3/connectionpool.py", line 376, in _make_request
    self._validate_conn(conn)
  File "/Library/Python/3.7/site-packages/urllib3/connectionpool.py", line 994, in _validate_conn
    conn.connect()
  File "/Library/Python/3.7/site-packages/urllib3/connection.py", line 360, in connect
    ssl_context=context,
  File "/Library/Python/3.7/site-packages/urllib3/util/ssl_.py", line 370, in ssl_wrap_socket
    return context.wrap_socket(sock, server_hostname=server_hostname)
  File "/Applications/Xcode.app/Contents/Developer/Library/Frameworks/Python3.framework/Versions/3.7/lib/python3.7/ssl.py", line 412, in wrap_socket
    session=session
  File "/Applications/Xcode.app/Contents/Developer/Library/Frameworks/Python3.framework/Versions/3.7/lib/python3.7/ssl.py", line 853, in _create
    self.do_handshake()
  File "/Applications/Xcode.app/Contents/Developer/Library/Frameworks/Python3.framework/Versions/3.7/lib/python3.7/ssl.py", line 1117, in do_handshake
    self._sslobj.do_handshake()
urllib3.exceptions.ProtocolError: ('Connection aborted.', ConnectionResetError(54, 'Connection reset by peer'))

During handling of the above exception, another exception occurred:

Traceback (most recent call last):
  File "jobs/hot_user.py", line 144, in <module>
    main()
  File "jobs/hot_user.py", line 68, in main
    upload_hot_users(like_most_users, "likeCount", headers)
  File "jobs/hot_user.py", line 139, in upload_hot_users
    raw = requests.post(url="https://api.bmob.cn/1/batch/", data=body, headers=headers)
  File "/Library/Python/3.7/site-packages/requests/api.py", line 116, in post
    return request('post', url, data=data, json=json, **kwargs)
  File "/Library/Python/3.7/site-packages/requests/api.py", line 60, in request
    return session.request(method=method, url=url, **kwargs)
  File "/Library/Python/3.7/site-packages/requests/sessions.py", line 533, in request
    resp = self.send(prep, **send_kwargs)
  File "/Library/Python/3.7/site-packages/requests/sessions.py", line 646, in send
    r = adapter.send(request, **kwargs)
  File "/Library/Python/3.7/site-packages/requests/adapters.py", line 498, in send
    raise ConnectionError(err, request=request)
requests.exceptions.ConnectionError: ('Connection aborted.', ConnectionResetError(54, 'Connection reset by peer'))
Build step 'Execute shell' marked build as failure
Finished: FAILURE
