Started by timer
Running as SYSTEM
Building in workspace /var/root/.jenkins/workspace/hourly-approval
No credentials specified
 > git rev-parse --is-inside-work-tree # timeout=10
Fetching changes from the remote Git repository
 > git config remote.origin.url git@github.com:kirinisland/zaoci-tool.git # timeout=10
Fetching upstream changes from git@github.com:kirinisland/zaoci-tool.git
 > git --version # timeout=10
 > git fetch --tags --force --progress -- git@github.com:kirinisland/zaoci-tool.git +refs/heads/*:refs/remotes/origin/* # timeout=10
 > git rev-parse refs/remotes/origin/master^{commit} # timeout=10
 > git rev-parse refs/remotes/origin/origin/master^{commit} # timeout=10
Checking out Revision f7a59245dcf59ce821289a6561f4e6368a475558 (refs/remotes/origin/master)
 > git config core.sparsecheckout # timeout=10
 > git checkout -f f7a59245dcf59ce821289a6561f4e6368a475558 # timeout=10
Commit message: "path updates"
 > git rev-list --no-walk f7a59245dcf59ce821289a6561f4e6368a475558 # timeout=10
[hourly-approval] $ /bin/sh -xe /var/folders/zz/zyxvpxvq6csfxvn_n0000000000000/T/jenkins6414103872186902208.sh
+ python3 jobs/filter_lyric.py
Traceback (most recent call last):
  File "/Library/Python/3.7/site-packages/urllib3/connection.py", line 157, in _new_conn
    (self._dns_host, self.port), self.timeout, **extra_kw
  File "/Library/Python/3.7/site-packages/urllib3/util/connection.py", line 84, in create_connection
    raise err
  File "/Library/Python/3.7/site-packages/urllib3/util/connection.py", line 74, in create_connection
    sock.connect(sa)
TimeoutError: [Errno 60] Operation timed out

During handling of the above exception, another exception occurred:

Traceback (most recent call last):
  File "/Library/Python/3.7/site-packages/urllib3/connectionpool.py", line 672, in urlopen
    chunked=chunked,
  File "/Library/Python/3.7/site-packages/urllib3/connectionpool.py", line 376, in _make_request
    self._validate_conn(conn)
  File "/Library/Python/3.7/site-packages/urllib3/connectionpool.py", line 994, in _validate_conn
    conn.connect()
  File "/Library/Python/3.7/site-packages/urllib3/connection.py", line 300, in connect
    conn = self._new_conn()
  File "/Library/Python/3.7/site-packages/urllib3/connection.py", line 169, in _new_conn
    self, "Failed to establish a new connection: %s" % e
urllib3.exceptions.NewConnectionError: <urllib3.connection.VerifiedHTTPSConnection object at 0x10b2662b0>: Failed to establish a new connection: [Errno 60] Operation timed out

During handling of the above exception, another exception occurred:

Traceback (most recent call last):
  File "/Library/Python/3.7/site-packages/requests/adapters.py", line 449, in send
    timeout=timeout
  File "/Library/Python/3.7/site-packages/urllib3/connectionpool.py", line 720, in urlopen
    method, url, error=e, _pool=self, _stacktrace=sys.exc_info()[2]
  File "/Library/Python/3.7/site-packages/urllib3/util/retry.py", line 436, in increment
    raise MaxRetryError(_pool, url, error or ResponseError(cause))
urllib3.exceptions.MaxRetryError: HTTPSConnectionPool(host='api2.bmob.cn', port=443): Max retries exceeded with url: /1/classes/EverydayLyric?where=%7B%22validStatus%22%3A%200%7D (Caused by NewConnectionError('<urllib3.connection.VerifiedHTTPSConnection object at 0x10b2662b0>: Failed to establish a new connection: [Errno 60] Operation timed out'))

During handling of the above exception, another exception occurred:

Traceback (most recent call last):
  File "jobs/filter_lyric.py", line 84, in <module>
    main()
  File "jobs/filter_lyric.py", line 48, in main
    raw = requests.get(url, headers=headers)
  File "/Library/Python/3.7/site-packages/requests/api.py", line 75, in get
    return request('get', url, params=params, **kwargs)
  File "/Library/Python/3.7/site-packages/requests/api.py", line 60, in request
    return session.request(method=method, url=url, **kwargs)
  File "/Library/Python/3.7/site-packages/requests/sessions.py", line 533, in request
    resp = self.send(prep, **send_kwargs)
  File "/Library/Python/3.7/site-packages/requests/sessions.py", line 646, in send
    r = adapter.send(request, **kwargs)
  File "/Library/Python/3.7/site-packages/requests/adapters.py", line 516, in send
    raise ConnectionError(e, request=request)
requests.exceptions.ConnectionError: HTTPSConnectionPool(host='api2.bmob.cn', port=443): Max retries exceeded with url: /1/classes/EverydayLyric?where=%7B%22validStatus%22%3A%200%7D (Caused by NewConnectionError('<urllib3.connection.VerifiedHTTPSConnection object at 0x10b2662b0>: Failed to establish a new connection: [Errno 60] Operation timed out'))
Build step 'Execute shell' marked build as failure
Finished: FAILURE
